Workbook

Sheet 船型列表
A1: 序号 | B1: 船型名称
B2: 3号船

Sheet 保障站位列表
A1: 站位编号 | B1: 站位名称 | C1: 一站式保障位 | D1: 可试车 | E1: 可挂弹 | F1: 可接地 | G1: 初始布列停放机型 | H1: 可停机型
A2: A1 | B2: A1 | D2: 1 | E2: 1 | F2: 1 | G2: F35 | H2: F15/F35/E2D/Z20
A3: A2 | B3: A2 | D3: 1 | E3: 1 | F3: 1 | G3: F35 | H3: F15/F35/E2D/Z20
A4: A3 | B4: A3 | D4: 1 | E4: 1 | F4: 1 | G4: F35 | H4: F15/F35/E2D/Z20
A5: A4 | B5: A4 | D5: 1 | E5: 1 | F5: 1 | G5: F35 | H5: F15/F35/E2D/Z20
A6: A5 | B6: A5 | D6: 1 | E6: 1 | F6: 1 | G6: F35 | H6: F15/F35/E2D/Z20
A7: A6 | B7: A6 | D7: 1 | E7: 1 | F7: 1 | G7: F35 | H7: F15/F35/E2D/Z20
A8: A7 | B8: A7 | D8: 1 | E8: 1 | F8: 1 | G8: F35 | H8: F15/F35/E2D/Z20
A9: A8 | B9: A8 | D9: 1 | E9: 1 | F9: 1 | G9: F35 | H9: F15/F35/E2D/Z20
A10: A9 | B10: A9 | D10: 1 | E10: 1 | F10: 1 | G10: F35 | H10: F15/F35/E2D/Z20
A11: A10 | B11: A10 | D11: 1 | E11: 1 | F11: 1 | G11: F35 | H11: F15/F35/E2D/Z20
A12: A11 | B12: A11 | D12: 1 | E12: 1 | F12: 1 | G12: F35 | H12: F15/F35/E2D/Z20
A13: A12 | B13: A12 | D13: 1 | E13: 1 | F13: 1 | G13: Z20 | H13: F15/F35/E2D/Z20
A14: A13 | B14: A13 | D14: 1 | E14: 1 | F14: 1 | G14: E2D | H14: F15/F35/E2D/Z20
A15: C1 | B15: C1 | D15: 1 | E15: 1 | F15: 1 | H15: F15/F35/E2D/Z20
A16: C2 | B16: C2 | D16: 1 | E16: 1 | F16: 1 | H16: F15/F35/E2D/Z20
A17: C3 | B17: C3 | D17: 1 | E17: 1 | F17: 1 | G17: E2D | H17: F15/F35/E2D/Z20
A18: E1 | B18: E1 | D18: 1 | E18: 1 | F18: 1 | G18: Z20 | H18: F15/F35/E2D/Z20
A19: E2 | B19: E2 | D19: 1 | E19: 1 | F19: 1 | G19: Z20 | H19: F15/F35/E2D/Z20
A20: P1 | B20: P1 | C20: 1 | D20: 1 | E20: 1 | F20: 1 | H20: F15/F35/E2D/Z20
A21: P1A | B21: P1A | C21: 1 | D21: 1 | E21: 1 | F21: 1 | H21: F15/F35/E2D/Z20
A22: P2 | B22: P2 | C22: 1 | D22: 1 | E22: 1 | F22: 1 | H22: F15/F35/E2D/Z20
A23: P2A | B23: P2A | C23: 1 | D23: 1 | E23: 1 | F23: 1 | H23: F15/F35/E2D/Z20
A24: P3 | B24: P3 | C24: 1 | D24: 1 | E24: 1 | F24: 1 | G24: F35 | H24: F15/F35/E2D/Z20
A25: P4 | B25: P4 | C25: 1 | D25: 1 | E25: 1 | F25: 1 | G25: F35 | H25: F15/F35/E2D/Z20
A26: P5 | B26: P5 | C26: 1 | D26: 1 | E26: 1 | F26: 1 | G26: F35 | H26: F15/F35/E2D/Z20
A27: P6 | B27: P6 | C27: 1 | D27: 1 | E27: 1 | F27: 1 | G27: F35 | H27: F15/F35/E2D/Z20
A28: P7 | B28: P7 | C28: 1 | D28: 1 | E28: 1 | F28: 1 | G28: F35 | H28: F15/F35/E2D/Z20
A29: P8 | B29: P8 | C29: 1 | D29: 1 | E29: 1 | F29: 1 | G29: F35 | H29: F15/F35/E2D/Z20
A30: P9 | B30: P9 | C30: 1 | D30: 1 | E30: 1 | F30: 1 | G30: F35 | H30: F15/F35/E2D/Z20
A31: P10 | B31: P10 | C31: 1 | D31: 1 | E31: 1 | F31: 1 | G31: F35 | H31: F15/F35/E2D/Z20
A32: PK-01 | B32: PK-01 | H32: F15/F35/E2D/Z20
A33: PK-02 | B33: PK-02 | H33: F15/F35/E2D/Z20
A34: PK-03 | B34: PK-03 | H34: F15/F35/E2D/Z20
A35: PK-04 | B35: PK-04 | H35: F15/F35/E2D/Z20
A36: PK-05 | B36: PK-05 | H36: F15/F35/E2D/Z20
A37: PK-06 | B37: PK-06 | H37: F15/F35/E2D/Z20
A38: PK-07 | B38: PK-07 | H38: F15/F35/E2D/Z20
A39: PK-08 | B39: PK-08 | H39: F15/F35/E2D/Z20
A40: PK-09 | B40: PK-09 | H40: F15/F35/E2D/Z20
...

Sheet 保障设施列表
A1: 序号 | B1: 功能 | C1: 设施编号 | D1: 备注
A2: 1 | B2: 供氧 | C2: YQ01
A3: 2 | B3: 供氧 | C3: GD02
A4: 3 | B4: 供氧 | C4: YQ02
A5: 4 | B5: 供氧 | C5: YQ03
A6: 5 | B6: 供氧 | C6: YQ04
A7: 6 | B7: 供氧 | C7: GD05
A8: 7 | B8: 供氧 | C8: YQ05
A9: 8 | B9: 供氧 | C9: YQ06
A10: 9 | B10: 供氮 | C10: DQ01
A11: 10 | B11: 供氮 | C11: DQ05
A12: 11 | B12: 供氮 | C12: DQ02
A13: 12 | B13: 供氮 | C13: DQ03
... A134: 133 | B134: 设备舱空调 | C134: SKT24

Sheet 保障设施功能
A1: 功能
A2: 供氧
A3: 供氮
A4: 供电
A5: 加油
A6: 座舱空调
A7: 惯导
A8: 液冷
A9: 液压
A10: 设备舱空调
A11: 试车
A12: 挂弹

Sheet 保障站位-设施关联矩阵
A1: 序号 | B1: 站位 | C1: 惯导 | D1: 座舱空调 | E1: 加油 | F1: 液压 | G1: 设备舱空调 | H1: 供氮 | I1: 供电 | J1: 供氧 | K1: 液冷
A2: 1 | B2: A13 | C2: YDZ04 | D2: ZKT09 | E2: JY06/JY07 | F2: YY02 | G2: SKT09 | H2: DQ03 | I2: GD07G/GD08G/GD09G
A3: 2 | B3: A12 | C3: YDZ04 | D3: ZKT07/ZKT09 | E3: JY06 | F3: YY02 | H3: DQ03 | I3: GD06G/GD07G/GD08G
A4: 3 | B4: A11 | C4: YDZ03 | D4: ZKT08 | E4: JY06 | G4: SKT07 | I4: GD06G
A5: 4 | B5: C3 | C5: YDZ04 | D5: ZKT06/ZKT07 | E5: JY05 | G5: SKT06 | H5: DQ02 | I5: GD05G
A6: 5 | B6: C2 | C6: YDZ02 | D6: ZKT04 | E6: JY03 | G6: SKT04/SKT05 | I6: GD04G
A7: 6 | B7: P1A | C7: YDZ01 | E7: JY02/JY09 | F7: YY01 | G7: SKT02/SKT03 | H7: DQ01 | I7: GD15G | J7: YQ01
A8: 7 | B8: P2A | C8: YDZ01 | E8: JY01 | F8: YY03 | H8: DQ01/DQ05 | I8: GD01G/GD02G/GD14G | J8: YQ01
A9: 8 | B9: P1 | C9: YDZ01 | D9: ZKT01 | E9: JY09 | F9: YY03 | G9: SKT01 | H9: DQ05 | I9: GD02G | J9: YQ01
A10: 9 | B10: P2 | C10: YDZ01 | D10: ZKT01 | E10: JY01/JY05 | F10: YY03 | G10: SKT01 | H10: DQ01/DQ05 | I10: GD01G/GD08G/GD09G
A11: 10 | B11: P3 | C11: YDZ01 | D11: ZKT11 | E11: JY08/JY09 | F11: YY03 | G11: SKT11 | H11: DQ04/DQ05 | I11: GD13G/GD14G | J11: YQ01
A12: 11 | B12: P4 | C12: YDZ01 | D12: ZKT12 | E12: JY09/JY10 | F12: YY03 | G12: SKT12 | H12: DQ05 | I12: GD15G | J12: YQ01
A13: 12 | B13: P5 | C13: YDZ05/YDZ06 | D13: ZKT13 | E13: JY10/JY11 | G13: SKT13 | I13: GD15G/GD16G/GD17G | J13: YQ01/GD02
A14: 13 | B14: P6 | C14: YDZ05/YDZ06 | D14: ZKT14 | E14: JY12 | F14: YY04 | G14: SKT14 | I14: GD16G/GD17G | J14: YQ02
A15: 14 | B15: P7 | E15: JY03/JY12/JY13 | F15: YY04 | H15: DQ06 | I15: GD04G/GD17G/GD18G
A16: 15 | B16: P8 | C16: YDZ07 | D16: ZKT04 | E16: JY03/JY14 | F16: YY05 | G16: SKT04/SKT05 | H16: DQ06 | I16: GD04G/GD18G/GD19G
A17: 16 | B17: P9 | C17: YDZ07 | D17: ZKT16 | E17: JY03/JY14 | F17: YY05 | I17: GD19G/GD20G | J17: YQ03
A18: 17 | B18: P10 | C18: YDZ07 | D18: ZKT17/ZKT18 | E18: JY14/JY15 | F18: YY05 | G18: SKT18 | H18: DQ08 | I18: GD19G/GD20G/GD21G | J18: YQ03
A19: 18 | B19: A7 | C19: YDZ10/YDZ11 | D19: ZKT22 | E19: JY18 | G19: SKT23 | H19: DQ10 | I19: GD24G/GD25G/GD26G | J19: YQ06
A20: 19 | B20: A8 | C20: YDZ10/YDZ11 | D20: ZKT22 | E20: JY18/JY19 | F20: YY07 | G20: SKT23 | H20: DQ10 | I20: GD25G/GD26G/GD27G/GD28G | J20: YQ06 | K20: YL01
A21: 20 | B21: A9 | C21: YDZ10/YDZ11 | D21: ZKT23 | E21: JY18/JY19 | F21: YY07 | G21: SKT24 | H21: DQ10 | I21: GD26G/GD27G/GD28G | J21: YQ06 | K21: YL01
A22: 21 | B22: A10 | C22: YDZ10/YDZ11 | D22: ZKT23 | E22: JY19 | F22: YY07 | G22: SKT24 | H22: DQ10 | I22: GD27G/GD28G | J22: YQ06 | K22: YL01
A23: 22 | B23: C1 | C23: YDZ05/YDZ06/YDZ07 | D23: ZKT15 | E23: JY03/JY13 | F23: YY05 | G23: SKT15 | H23: DQ06 | I23: GD04G/GD18G
A24: 23 | B24: E1 | C24: YDZ07 | D24: ZKT16 | E24: JY13/JY14 | F24: YY05 | G24: SKT16 | H24: DQ06/DQ07 | I24: GD19G | J24: YQ03
A25: 24 | B25: A1 | C25: YDZ07 | D25: ZKT16/ZKT17 | E25: JY14/JY15/JY16 | F25: YY05 | G25: SKT16 | H25: DQ07/DQ08 | I25: GD19G/GD20G | J25: YQ03
A26: 25 | B26: A2 | C26: YDZ07 | D26: ZKT17/ZKT18 | E26: JY15/JY16 | H26: DQ08 | I26: GD20G | J26: YQ04
A27: 26 | B27: A3 | C27: YDZ08/YDZ09 | D27: ZKT19 | E27: JY16 | G27: SKT19/SKT20 | H27: DQ08 | J27: YQ04
A28: 27 | B28: A4 | C28: YDZ08/YDZ09 | D28: ZKT20 | F28: YY06 | G28: SKT20 | J28: YQ04
A29: 28 | B29: A5 | C29: YDZ08/YDZ09 | D29: ZKT20/ZKT21 | E29: JY17 | F29: YY06 | G29: SKT21/SKT22 | H29: DQ09 | I29: GD22G/GD23G | J29: YQ04/GD05
A30: 29 | B30: A6 | C30: YDZ08/YDZ09 | D30: ZKT21 | E30: JY17 | F30: YY06 | G30: SKT22 | H30: DQ09 | I30: GD22G/GD23G | J30: YQ05
A31: 30 | B31: E2 | C31: YDZ10/YDZ11 | E31: JY17/JY18 | H31: DQ09 | I31: GD23G/GD24G

Sheet 装备结构树
A1: uid | B1: 层级 | C1: 机型名称 | D1: 上级节点 | E1: 节点名称 | F1: 型号 | G1: 数量（n） | H1: k中取n | I1: 是否为LRU | J1: 故障率 | K1: MTBCF | L1: 故障抽样分布 | M1: 平均修复时间（min） | N1: 修复时间抽样分布 | O1: 是否可被检测 | P1: 检测和隔离时间 | Q1: 功能描述 | R1: 性能描述
A2: =C2&"-"&ROW()-1 -> F35-1 | B2: 1 | C2: F35
A3: =C3&"-"&ROW()-1 -> F35-2 | B3: 2 | C3: F35 | D3: =A2 -> F35-1 | E3: 航电系统 | F3: SYS-AV-01 | G3: 2 | H3: 1 | O3: 否
A4: =C4&"-"&ROW()-1 -> F35-3 | B4: 3 | C4: F35 | D4: =A3 -> F35-2 | E4: 任务计算机模块 | F4: LRU-RW-01 | G4: 2 | H4: 1 | I4: 1 | J4: 0.0012 | L4: 指数分布 | N4: 指数分布 | O4: 否
A5: =C5&"-"&ROW()-1 -> F35-4 | B5: 3 | C5: F35 | D5: =A3 -> F35-2 | E5: 雷达接收机模块 | F5: LRU-LD-02 | G5: 1 | I5: 1 | J5: 0.0008 | L5: 指数分布 | N5: 指数分布 | O5: 否
A6: =C6&"-"&ROW()-1 -> F35-5 | B6: 3 | C6: F35 | D6: =A3 -> F35-2 | E6: 惯导处理模块 | F6: LRU-GD-03 | G6: 1 | I6: 1 | J6: 0.001 | L6: 指数分布 | N6: 指数分布 | O6: 否
A7: =C7&"-"&ROW()-1 -> F35-6 | B7: 2 | C7: F35 | D7: =A2 -> F35-1 | E7: 液压系统 | F7: SYS-HY-01 | G7: 2 | H7: 1 | O7: 否
A8: =C8&"-"&ROW()-1 -> F35-7 | B8: 3 | C8: F35 | D8: =A7 -> F35-6 | E8: 液压泵控制器 | F8: LRU-YY-01 | G8: 1 | I8: 1 | J8: 0.0025 | L8: 指数分布 | N8: 指数分布 | O8: 否
A9: =C9&"-"&ROW()-1 -> F35-8 | B9: 3 | C9: F35 | D9: =A7 -> F35-6 | E9: 作动筒监测组件 | F9: LRU-ZD-02 | G9: 1 | I9: 1 | J9: 0.0019 | L9: 指数分布 | N9: 指数分布 | O9: 否
A10: =C10&"-"&ROW()-1 -> F35-9 | B10: 2 | C10: F35 | D10: =A2 -> F35-1 | E10: 动力系统 | F10: SYS-DL-01 | G10: 1 | O10: 否
A11: =C11&"-"&ROW()-1 -> F35-10 | B11: 3 | C11: F35 | D11: =A10 -> F35-9 | E11: 燃油计量控制器 | F11: LRU-RY-01 | G11: 1 | I11: 1 | J11: 0.0016 | L11: 指数分布 | N11: 指数分布 | O11: 否
A12: =C12&"-"&ROW()-1 -> F35-11 | B12: 3 | C12: F35 | D12: =A10 -> F35-9 | E12: 起动控制盒 | F12: LRU-QD-02 | G12: 1 | I12: 1 | J12: 0.0011 | L12: 指数分布 | N12: 指数分布 | O12: 否
A13: =C13&"-"&ROW()-1 -> Z20-12 | B13: 1 | C13: Z20
A14: =C14&"-"&ROW()-1 -> Z20-13 | B14: 2 | C14: Z20 | D14: =A13 -> Z20-12 | E14: 通信导航系统 | F14: SYS-TX-01 | G14: 1 | O14: 否
A15: =C15&"-"&ROW()-1 -> Z20-14 | B15: 3 | C15: Z20 | D15: =A14 -> Z20-13 | E15: 北斗导航接收机 | F15: LRU-BD-01 | G15: 1 | I15: 1 | J15: 0.0015 | L15: 指数分布 | N15: 指数分布 | O15: 否
A16: =C16&"-"&ROW()-1 -> Z20-15 | B16: 3 | C16: Z20 | D16: =A14 -> Z20-13 | E16: 机载通信终端 | F16: LRU-TX-02 | G16: 1 | I16: 1 | J16: 0.0017 | L16: 指数分布 | N16: 指数分布 | O16: 否
A17: =C17&"-"&ROW()-1 -> Z20-16 | B17: 2 | C17: Z20 | D17: =A13 -> Z20-12 | E17: 旋翼传动系统 | F17: SYS-XY-01 | G17: 2 | O17: 否
A18: =C18&"-"&ROW()-1 -> Z20-17 | B18: 3 | C18: Z20 | D18: =A17 -> Z20-16 | E18: 主减速器监测单元 | F18: LRU-JS-01 | G18: 1 | I18: 1 | J18: 0.0021 | L18: 指数分布 | N18: 指数分布 | O18: 否
A19: =C19&"-"&ROW()-1 -> Z20-18 | B19: 3 | C19: Z20 | D19: =A17 -> Z20-16 | E19: 尾桨控制组件 | F19: LRU-WJ-02 | G19: 1 | I19: 1 | J19: 0.0014 | L19: 指数分布 | N19: 指数分布 | O19: 否
A20: =C20&"-"&ROW()-1 -> F15-19 | B20: 1 | C20: F15
A21: =C21&"-"&ROW()-1 -> F15-20 | B21: 2 | C21: F15 | D21: =A20 -> F15-19 | E21: 武器控制系统 | F21: SYS-WQ-01 | G21: 2 | H21: 1 | O21: 否
A22: =C22&"-"&ROW()-1 -> F15-21 | B22: 3 | C22: F15 | D22: =A21 -> F15-20 | E22: 火控处理器 | F22: LRU-HK-01 | G22: 1 | I22: 1 | J22: 0.0013 | L22: 指数分布 | N22: 指数分布 | O22: 否
A23: =C23&"-"&ROW()-1 -> F15-22 | B23: 3 | C23: F15 | D23: =A21 -> F15-20 | E23: 挂架接口模块 | F23: LRU-GJ-02 | G23: 2 | H23: 1 | I23: 1 | J23: 0.0018 | L23: 指数分布 | N23: 指数分布 | O23: 否
A24: =C24&"-"&ROW()-1 -> F15-23 | B24: 2 | C24: F15 | D24: =A20 -> F15-19 | E24: 起落架系统 | F24: SYS-QL-01 | G24: 1 | O24: 否
A25: =C25&"-"&ROW()-1 -> F15-24 | B25: 3 | C25: F15 | D25: =A24 -> F15-23 | E25: 前起控制组件 | F25: LRU-QQ-01 | G25: 1 | I25: 1 | J25: 0.0022 | L25: 指数分布 | N25: 指数分布 | O25: 否
A26: =C26&"-"&ROW()-1 -> F15-25 | B26: 3 | C26: F15 | D26: =A24 -> F15-23 | E26: 刹车控制阀组 | F26: LRU-SC-02 | G26: 1 | I26: 1 | J26: 0.0016 | L26: 指数分布 | N26: 指数分布 | O26: 否
A27: =C27&"-"&ROW()-1 -> E2D-26 | B27: 1 | C27: E2D
A28: =C28&"-"&ROW()-1 -> E2D-27 | B28: 2 | C28: E2D | D28: =A27 -> E2D-26 | E28: 任务雷达系统 | F28: SYS-RD-01 | G28: 1 | O28: 否
A29: =C29&"-"&ROW()-1 -> E2D-28 | B29: 3 | C29: E2D | D29: =A28 -> E2D-27 | E29: 相控阵收发模块 | F29: LRU-XKZ-01 | G29: 2 | H29: 1 | I29: 1 | J29: 0.0011 | L29: 指数分布 | N29: 指数分布 | O29: 否
A30: =C30&"-"&ROW()-1 -> E2D-29 | B30: 3 | C30: E2D | D30: =A28 -> E2D-27 | E30: 任务处理服务器 | F30: LRU-RW-KE-01 | G30: 1 | I30: 1 | J30: 0.0009 | L30: 指数分布 | N30: 指数分布 | O30: 否
A31: =C31&"-"&ROW()-1 -> E2D-30 | B31: 2 | C31: E2D | D31: =A27 -> E2D-26 | E31: 数据链通信系统 | F31: SYS-DL-KE-01 | G31: 1 | O31: 否
A32: =C32&"-"&ROW()-1 -> E2D-31 | B32: 3 | C32: E2D | D32: =A31 -> E2D-30 | E32: 宽带数据链终端 | F32: LRU-DL-01 | G32: 1 | I32: 1 | J32: 0.0012 | L32: 指数分布 | N32: 指数分布 | O32: 否
A33: =C33&"-"&ROW()-1 -> E2D-32 | B33: 3 | C33: E2D | D33: =A31 -> E2D-30 | E33: 卫通加密模块 | F33: LRU-WT-01 | G33: 1 | I33: 1 | J33: 0.001 | L33: 指数分布 | N33: 指数分布 | O33: 否

Sheet 飞机池列表
A1: 序号 | B1: 机型 | C1: 飞机编号 | D1: 保障组织 | E1: 现处状态 | F1: 出厂日期 | G1: 总规定年限 | H1: 总规定寿命 | I1: 总规定起落 | J1: 总飞行时间 | K1: 总起落次数 | L1: 翻修后规定年限 | M1: 翻修后总规定寿命 | N1: 翻修后规定起落 | O1: 飞行时间 | P1: 剩余寿命 | Q1: 飞行起落次数
A2: 1 | B2: F35 | C2: F35-01 | D2: 舰载战斗机分队 | E2: 在册完好 | F2: 2019-01-15 | G2: 30 | H2: 2003:00 | I2: 3012 | J2: 277:15 | K2: 292 | L2: 8年 | M2: 1002:00 | N2: 1508 | O2: 277:15 | P2: 724:45 | Q2: 292
A3: 2 | B3: F35 | C3: F35-02 | D3: 舰载战斗机分队 | E3: 在册完好 | F3: 2018-02-15 | G3: 30 | H3: 2006:00 | I3: 3024 | J3: 278:30 | K3: 297 | L3: 8年 | M3: 1004:00 | N3: 1516 | O3: 278:30 | P3: 725:30 | Q3: 297
A4: 3 | B4: F35 | C4: F35-03 | D4: 舰载战斗机分队 | E4: 在册完好 | F4: 2017-03-15 | G4: 30 | H4: 2009:00 | I4: 3036 | J4: 279:45 | K4: 302 | L4: 8年 | M4: 1006:00 | N4: 1524 | O4: 279:45 | P4: 726:15 | Q4: 302
A5: 4 | B5: F35 | C5: F35-04 | D5: 舰载战斗机分队 | E5: 在册完好 | F5: 2016-04-15 | G5: 30 | H5: 2012:00 | I5: 3048 | J5: 281:00 | K5: 307 | L5: 8年 | M5: 1008:00 | N5: 1532 | O5: 281:00 | P5: 727:00 | Q5: 307
A6: 5 | B6: F35 | C6: F35-05 | D6: 舰载战斗机分队 | E6: 在册完好 | F6: 2019-05-15 | G6: 30 | H6: 2015:00 | I6: 3060 | J6: 282:15 | K6: 312 | L6: 8年 | M6: 1010:00 | N6: 1540 | O6: 282:15 | P6: 727:45 | Q6: 312
A7: 6 | B7: F35 | C7: F35-06 | D7: 舰载战斗机分队 | E7: 在册完好 | F7: 2018-06-15 | G7: 30 | H7: 2018:00 | I7: 3072 | J7: 283:30 | K7: 317 | L7: 8年 | M7: 1012:00 | N7: 1548 | O7: 283:30 | P7: 728:30 | Q7: 317
A8: 7 | B8: F35 | C8: F35-07 | D8: 舰载战斗机分队 | E8: 在册完好 | F8: 2017-07-15 | G8: 30 | H8: 2021:00 | I8: 3084 | J8: 284:45 | K8: 322 | L8: 8年 | M8: 1014:00 | N8: 1556 | O8: 284:45 | P8: 729:15 | Q8: 322
A9: 8 | B9: F35 | C9: F35-08 | D9: 舰载战斗机分队 | E9: 在册完好 | F9: 2016-08-15 | G9: 30 | H9: 2024:00 | I9: 3096 | J9: 286:00 | K9: 327 | L9: 8年 | M9: 1016:00 | N9: 1564 | O9: 286:00 | P9: 730:00 | Q9: 327
A10: 9 | B10: F35 | C10: F35-09 | D10: 舰载战斗机分队 | E10: 在册完好 | F10: 2019-09-15 | G10: 30 | H10: 2027:00 | I10: 3108 | J10: 287:15 | K10: 332 | L10: 8年 | M10: 1018:00 | N10: 1572 | O10: 287:15 | P10: 730:45 | Q10: 332
A11: 10 | B11: F35 | C11: F35-10 | D11: 舰载战斗机分队 | E11: 在册完好 | F11: 2018-10-15 | G11: 30 | H11: 2030:00 | I11: 3120 | J11: 288:30 | L11: 8年 | M11: 1020:00 | N11: 1580 | O11: 288:30 | P11: 731:30
A12: 11 | B12: F35 | C12: F35-11 | D12: 舰载战斗机分队 | E12: 在册完好 | F12: 2017-11-15 | G12: 30 | H12: 2033:00 | I12: 3132 | J12: 289:45 | K12: 342 | L12: 8年 | M12: 1022:00 | N12: 1588 | O12: 289:45 | P12: 732:15 | Q12: 342
A13: 12 | B13: F35 | C13: F35-12 | D13: 舰载战斗机分队 | E13: 在册完好 | F13: 2016-12-15 | G13: 30 | H13: 2036:00 | I13: 3144 | J13: 291:00 | K13: 347 | L13: 8年 | M13: 1024:00 | N13: 1596 | O13: 291:00 | P13: 733:00 | Q13: 347
A14: 13 | B14: F35 | C14: F35-13 | D14: 舰载战斗机分队 | E14: 在册完好 | F14: 2019-01-15 | G14: 30 | H14: 2039:00 | I14: 3156 | J14: 292:15 | K14: 352 | L14: 8年 | M14: 1026:00 | N14: 1604 | O14: 292:15 | P14: 733:45 | Q14: 352
A15: 14 | B15: F35 | C15: F35-14 | D15: 舰载战斗机分队 | E15: 在册完好 | F15: 2019-01-15 | G15: 30 | H15: 2039:00 | I15: 3156 | J15: 292:15 | K15: 352 | L15: 8年 | M15: 1026:00 | N15: 1604 | O15: 292:15 | P15: 733:45 | Q15: 352
A16: 15 | B16: F35 | C16: F35-15 | D16: 舰载战斗机分队 | E16: 在册完好 | F16: 2019-01-15 | G16: 30 | H16: 2039:00 | I16: 3156 | J16: 292:15 | K16: 352 | L16: 8年 | M16: 1026:00 | N16: 1604 | O16: 292:15 | P16: 733:45 | Q16: 352
A17: 16 | B17: F35 | C17: F35-16 | D17: 舰载战斗机分队 | E17: 在册完好 | F17: 2019-01-15 | G17: 30 | H17: 2039:00 | I17: 3156 | J17: 292:15 | K17: 352 | L17: 8年 | M17: 1026:00 | N17: 1604 | O17: 292:15 | P17: 733:45 | Q17: 352
A18: 17 | B18: F35 | C18: F35-17 | D18: 舰载战斗机分队 | E18: 在册完好 | F18: 2019-01-15 | G18: 30 | H18: 2039:00 | I18: 3156 | J18: 292:15 | K18: 352 | L18: 8年 | M18: 1026:00 | N18: 1604 | O18: 292:15 | P18: 733:45 | Q18: 352
A19: 18 | B19: F35 | C19: F35-18 | D19: 舰载战斗机分队 | E19: 在册完好 | F19: 2019-01-15 | G19: 30 | H19: 2039:00 | I19: 3156 | J19: 292:15 | K19: 352 | L19: 8年 | M19: 1026:00 | N19: 1604 | O19: 292:15 | P19: 733:45 | Q19: 352
A20: 19 | B20: F35 | C20: F35-19 | D20: 舰载战斗机分队 | E20: 在册完好 | F20: 2019-01-15 | G20: 30 | H20: 2039:00 | I20: 3156 | J20: 292:15 | K20: 352 | L20: 8年 | M20: 1026:00 | N20: 1604 | O20: 292:15 | P20: 733:45 | Q20: 352
A21: 20 | B21: F35 | C21: F35-20 | D21: 舰载战斗机分队 | E21: 在册完好 | F21: 2019-01-15 | G21: 30 | H21: 2039:00 | I21: 3156 | J21: 292:15 | K21: 352 | L21: 8年 | M21: 1026:00 | N21: 1604 | O21: 292:15 | P21: 733:45 | Q21: 352
A22: 21 | B22: F35 | C22: F35-21 | D22: 舰载战斗机分队 | E22: 在册完好 | F22: 2019-01-15 | G22: 30 | H22: 2039:00 | I22: 3156 | J22: 292:15 | K22: 352 | L22: 8年 | M22: 1026:00 | N22: 1604 | O22: 292:15 | P22: 733:45 | Q22: 352
A23: 22 | B23: F35 | C23: F35-22 | D23: 舰载战斗机分队 | E23: 在册完好 | F23: 2019-01-15 | G23: 30 | H23: 2039:00 | I23: 3156 | J23: 292:15 | K23: 352 | L23: 8年 | M23: 1026:00 | N23: 1604 | O23: 292:15 | P23: 733:45 | Q23: 352
... A42: 41 | B42: E2D | C42: E2D-04 | D42: 舰载预警机分队 | E42: 在册完好 | F42: 2015-04-15 | G42: 28 | H42: 2012:00 | I42: 3048 | J42: 281:00 | K42: 307 | L42: 8年 | M42: 1008:00 | N42: 1532 | O42: 281:00 | P42: 727:00 | Q42: 307

Sheet 保障组织结构树
A1: id | B1: 层级 | C1: 组织名称 | D1: 上级组织 | E1: uid
A2: z01 | B2: 1 | C2: 航空联队（机务） | E2: =A2 -> z01
A3: z02 | B3: 2 | C3: 舰载战斗机分队 | D3: z01 | E3: =A3 -> z02
A4: z03 | B4: 3 | C4: 放飞保障组 | D4: z02 | E4: =A4 -> z03
A5: z04 | B5: 4 | C5: 放飞组 | D5: z03 | E5: =A5 -> z04
A6: z05 | B6: 4 | C6: 流道组 | D6: z03 | E6: =A6 -> z05
A7: z06 | B7: 3 | C7: 技术保障组 | D7: =A3 -> z02 | E7: =A7 -> z06
A8: z07 | B8: 4 | C8: 机电组 | D8: =A7 -> z06 | E8: =A8 -> z07
A9: z08 | B9: 4 | C9: 军械组 | D9: =D8 -> z06 | E9: =A9 -> z08
A10: z09 | B10: 4 | C10: 航电组 | D10: =D9 -> z06 | E10: =A10 -> z09
A11: z10 | B11: 4 | C11: 飞参组 | D11: =D10 -> z06 | E11: =A11 -> z10
A12: z11 | B12: 4 | C12: 发监组 | D12: =D11 -> z06 | E12: =A12 -> z11
A13: z12 | B13: 3 | C13: 修理保障组 | D13: =A3 -> z02 | E13: =A13 -> z12
A14: z13 | B14: 4 | C14: 附件组 | D14: =A13 -> z12 | E14: =A14 -> z13
A15: z14 | B15: 4 | C15: 机加组 | D15: =D14 -> z12 | E15: =A15 -> z14
A16: z15 | B16: 4 | C16: 油液分析组 | D16: =D15 -> z12 | E16: =A16 -> z15
A17: z16 | B17: 4 | C17: 探伤组 | D17: =D16 -> z12 | E17: =A17 -> z16
A18: z17 | B18: 2 | C18: 舰载直升机分队 | D18: z01 | E18: =A18 -> z17
A19: z18 | B19: 2 | C19: 舰载预警机分队 | D19: z01 | E19: =A19 -> z18
A20: z19 | B20: 1 | C20: 航空联队（勤务） | E20: =A20 -> z19
A21: z20 | B21: 2 | C21: 调运中队 | D21: z19 | E21: =A21 -> z20
A22: z21 | B22: 3 | C22: 机械区队 | D22: =A21 -> z20 | E22: =A22 -> z21
A23: z22 | B23: 3 | C23: 转运区队 | D23: =D22 -> z20 | E23: =A23 -> z22
A24: z23 | B24: 3 | C24: 信息调度引导区队 | D24: =D23 -> z20 | E24: =A24 -> z23
A25: z24 | B25: 2 | C25: 舰面保障中队 | D25: z19 | E25: =A25 -> z24
A26: z25 | B26: 3 | C26: 航空油料区队 | D26: =A25 -> z24 | E26: =A26 -> z25
A27: z26 | B27: 3 | C27: 气电区队 | D27: =D26 -> z24 | E27: =A27 -> z26
A28: z27 | B28: 3 | C28: 舰面支持设备区队 | D28: =D27 -> z24 | E28: =A28 -> z27
A29: z28 | B29: 3 | C29: 维修航材区队 | D29: =D28 -> z24 | E29: =A29 -> z28
A30: z29 | B30: 2 | C30: 起降保障中队 | D30: z19 | E30: =A30 -> z29
A31: z30 | B31: 3 | C31: 起飞系统区队 | D31: =A30 -> z29 | E31: =A31 -> z30
A32: z31 | B32: 3 | C32: 拦阻系统区队 | D32: =D31 -> z29 | E32: =A32 -> z31
A33: z32 | B33: 3 | C33: 着舰光学引导区队 | D33: =D32 -> z29 | E33: =A33 -> z32
A34: z33 | B34: 2 | C34: 机载弹药保障中队 | D34: z19 | E34: =A34 -> z33
A35: z34 | B35: 3 | C35: 保管测试区队 | D35: =A34 -> z33 | E35: =A35 -> z34
A36: z35 | B36: 3 | C36: 弹药转运区队 | D36: =A35 -> z34 | E36: =A36 -> z35

Sheet 保障人员
A1: 序号 | B1: 所属部门 | C1: 所属部门id | D1: 专业名称 | E1: 专业等级 | F1: 数量
A2: 1 | B2: 舰载战斗机分队 | C2: =VLOOKUP(B2,保障组织结构树!C:E,3,0) -> z02 | D2: 机械 | E2: 师 | F2: 8
A3: 2 | B3: 舰载战斗机分队 | C3: =VLOOKUP(B3,保障组织结构树!C:E,3,0) -> z02 | D3: 机械 | E3: 员 | F3: 8
A4: 3 | B4: 舰载战斗机分队 | C4: =VLOOKUP(B4,保障组织结构树!C:E,3,0) -> z02 | D4: 航电 | E4: 师 | F4: 8
A5: 4 | B5: 舰载战斗机分队 | C5: =VLOOKUP(B5,保障组织结构树!C:E,3,0) -> z02 | D5: 航电 | E5: 员 | F5: 8
A6: 5 | B6: 舰载战斗机分队 | C6: =VLOOKUP(B6,保障组织结构树!C:E,3,0) -> z02 | D6: 特设 | E6: 师 | F6: 8
A7: 6 | B7: 舰载战斗机分队 | C7: =VLOOKUP(B7,保障组织结构树!C:E,3,0) -> z02 | D7: 特设 | E7: 员 | F7: 8
A8: 7 | B8: 舰载战斗机分队 | C8: =VLOOKUP(B8,保障组织结构树!C:E,3,0) -> z02 | D8: 军械 | E8: 师 | F8: 8
A9: 8 | B9: 舰载战斗机分队 | C9: =VLOOKUP(B9,保障组织结构树!C:E,3,0) -> z02 | D9: 军械 | E9: 员 | F9: 8
A10: 9 | B10: 舰载直升机分队 | C10: =VLOOKUP(B10,保障组织结构树!C:E,3,0) -> z17 | D10: 机械 | E10: 师 | F10: 8
A11: 10 | B11: 舰载直升机分队 | C11: =VLOOKUP(B11,保障组织结构树!C:E,3,0) -> z17 | D11: 机械 | E11: 员 | F11: 8
A12: 11 | B12: 舰载直升机分队 | C12: =VLOOKUP(B12,保障组织结构树!C:E,3,0) -> z17 | D12: 航电 | E12: 师 | F12: 8
A13: 12 | B13: 舰载直升机分队 | C13: =VLOOKUP(B13,保障组织结构树!C:E,3,0) -> z17 | D13: 航电 | E13: 员 | F13: 8
... A25: 24 | B25: 舰载预警机分队 | C25: =VLOOKUP(B25,保障组织结构树!C:E,3,0) -> z18 | D25: 任务电子 | E25: 员 | F25: 8
A26: 26 | B26: 调运中队 | C26: =VLOOKUP(B26,保障组织结构树!C:E,3,0) -> z20 | D26: 转运组 | F26: 5
A27: 27 | B27: 舰面保障中队 | C27: =VLOOKUP(B27,保障组织结构树!C:E,3,0) -> z24 | D27: 加油组 | F27: 5
A28: 28 | B28: 舰面保障中队 | C28: =VLOOKUP(B28,保障组织结构树!C:E,3,0) -> z24 | D28: 流道组 | F28: 5
A29: 29 | B29: 舰面保障中队 | C29: =VLOOKUP(B29,保障组织结构树!C:E,3,0) -> z24 | D29: 舰面保障组 | F29: 5
A30: 30 | B30: 舰面保障中队 | C30: =VLOOKUP(B30,保障组织结构树!C:E,3,0) -> z24 | D30: 质检组 | F30: 5
A31: 31 | B31: 舰面保障中队 | C31: =VLOOKUP(B31,保障组织结构树!C:E,3,0) -> z24 | D31: 间隙异物组 | F31: 5
A32: 32 | B32: 舰面保障中队 | C32: =VLOOKUP(B32,保障组织结构树!C:E,3,0) -> z24 | D32: 放飞组 | F32: 5
A33: 33 | B33: 舰面保障中队 | C33: =VLOOKUP(B33,保障组织结构树!C:E,3,0) -> z24 | D33: 技术保障组 | F33: 5
A34: 34 | B34: 机载弹药保障中队 | C34: =VLOOKUP(B34,保障组织结构树!C:E,3,0) -> z33 | D34: 挂弹组 | F34: 5

Sheet 保障设备
A1: 序号 | B1: 名称 | C1: 型号 | D1: 设备-型号 | E1: 适用机型 | F1: 数量 | G1: 计量单位 | H1: 所属部门 | I1: 所属部门id
A2: 1 | B2: 登机梯 | C2: G/DJFT-1 | D2: =B2&"-"&C2 -> 登机梯-G/DJFT-1 | E2: F15 | F2: 1 | G2: 台 | H2: 航空联队（勤务） | I2: =VLOOKUP(H2,保障组织结构树!C:E,3,0) -> z19
A3: 2 | B3: 机下工作梯 | C3: G/JXFT-1 | D3: =B3&IF(C3<>"","-"&C3,"") -> 机下工作梯-G/JXFT-1 | E3: F15 | F3: 1 | G3: 台 | H3: 航空联队（勤务） | I3: =VLOOKUP(H3,保障组织结构树!C:E,3,0) -> z19
A4: 3 | B4: 前起落架舱工作梯 | C4: QQCT-1B | D4: =B4&IF(C4<>"","-"&C4,"") -> 前起落架舱工作梯-QQCT-1B | E4: F15 | F4: 1 | G4: 台 | H4: 航空联队（勤务） | I4: =VLOOKUP(H4,保障组织结构树!C:E,3,0) -> z19
A5: 4 | B5: 发动机拆装托车 | C5: F/FAC-3 | D5: =B5&IF(C5<>"","-"&C5,"") -> 发动机拆装托车-F/FAC-3 | E5: F15 | F5: 1 | G5: 套 | H5: 航空联队（勤务） | I5: =VLOOKUP(H5,保障组织结构树!C:E,3,0) -> z19
A6: 5 | B6: 发电机传动装置拆装设备 | C6: J15.9151.A.000.000 | D6: =B6&IF(C6<>"","-"&C6,"") -> 发电机传动装置拆装设备-J15.9151.A.000.000 | E6: F15 | F6: 1 | G6: 套 | H6: 航空联队（勤务） | I6: =VLOOKUP(H6,保障组织结构树!C:E,3,0) -> z19
A7: 6 | B7: 外置附件机匣放油软管 | C7: J15.9176.A.000.000 | D7: =B7&IF(C7<>"","-"&C7,"") -> 外置附件机匣放油软管-J15.9176.A.000.000 | E7: F15 | F7: 1 | G7: 套 | H7: 航空联队（勤务） | I7: =VLOOKUP(H7,保障组织结构树!C:E,3,0) -> z19
A8: 7 | B8: 发动机燃油和滑油排放软管 | C8: J15.9188.A.000.000 | D8: =B8&IF(C8<>"","-"&C8,"") -> 发动机燃油和滑油排放软管-J15.9188.A.000.000 | E8: F15 | F8: 1 | G8: 套 | H8: 航空联队（勤务） | I8: =VLOOKUP(H8,保障组织结构树!C:E,3,0) -> z19
A9: 8 | B9: 飞机机体蒙布 | C9: J/JTMF-2 | D9: =B9&IF(C9<>"","-"&C9,"") -> 飞机机体蒙布-J/JTMF-2 | E9: F15 | F9: 1 | G9: 台 | H9: 航空联队（勤务） | I9: =VLOOKUP(H9,保障组织结构树!C:E,3,0) -> z19
A10: 9 | B10: 进气道堵盖 | C10: J/JDHF-1 | D10: =B10&IF(C10<>"","-"&C10,"") -> 进气道堵盖-J/JDHF-1 | E10: F15 | F10: 1 | G10: 套 | H10: 航空联队（勤务） | I10: =VLOOKUP(H10,保障组织结构树!C:E,3,0) -> z19
A11: 10 | B11: 组合式充气检压装置 | C11: J/ZHTZ-1 | D11: =B11&IF(C11<>"","-"&C11,"") -> 组合式充气检压装置-J/ZHTZ-1 | E11: F15 | F11: 1 | G11: 台 | H11: 航空联队（勤务） | I11: =VLOOKUP(H11,保障组织结构树!C:E,3,0) -> z19
A12: 11 | B12: 飞机主千斤顶 | C12: J/ZZD-5 | D12: =B12&IF(C12<>"","-"&C12,"") -> 飞机主千斤顶-J/ZZD-5 | E12: F15 | F12: 1 | G12: 套 | H12: 航空联队（勤务） | I12: =VLOOKUP(H12,保障组织结构树!C:E,3,0) -> z19
A13: 12 | B13: 飞机前千斤顶 | C13: J/QZD-5A | D13: =B13&IF(C13<>"","-"&C13,"") -> 飞机前千斤顶-J/QZD-5A | E13: F15 | F13: 1 | G13: 台 | H13: 航空联队（勤务） | I13: =VLOOKUP(H13,保障组织结构树!C:E,3,0) -> z19
A14: 13 | B14: 主机轮千斤顶 | C14: ZQJD11-1A | D14: =B14&IF(C14<>"","-"&C14,"") -> 主机轮千斤顶-ZQJD11-1A | E14: F15 | F14: 1 | G14: 套 | H14: 航空联队（勤务） | I14: =VLOOKUP(H14,保障组织结构树!C:E,3,0) -> z19
... A47: 46 | B47: 导航外场检查仪 | C47: B/DHCSY-1/1 | D47: =B47&IF(C47<>"","-"&C47,"") -> 导航外场检查仪-B/DHCSY-1/1 | E47: F15 | F47: 1 | G47: 套 | H47: 航空联队（勤务） | I47: =VLOOKUP(H47,保障组织结构树!C:E,3,0) -> z19
A48: 47 | B48: 注油枪（黑油、白油） | D48: =B48&IF(C48<>"","-"&C48,"") -> 注油枪（黑油、白油） | E48: Z20 | F48: 2 | G48: 套 | H48: 舰载直升机分队 | I48: =VLOOKUP(H48,保障组织结构树!C:E,3,0) -> z17
A49: 48 | B49: 旋翼液压阻尼器注油枪（含卡簧钳） | D49: =B49&IF(C49<>"","-"&C49,"") -> 旋翼液压阻尼器注油枪（含卡簧钳） | E49: Z20 | F49: 1 | G49: 套 | H49: 舰载直升机分队 | I49: =VLOOKUP(H49,保障组织结构树!C:E,3,0) -> z17
A50: 49 | B50: 应急移动电源 | D50: =B50&IF(C50<>"","-"&C50,"") -> 应急移动电源 | E50: Z20 | F50: 1 | G50: 套 | H50: 舰载直升机分队 | I50: =VLOOKUP(H50,保障组织结构树!C:E,3,0) -> z17
A51: 50 | B51: 折叠辅助系统 | D51: =B51&IF(C51<>"","-"&C51,"") -> 折叠辅助系统 | E51: Z20 | F51: 1 | G51: 套 | H51: 舰载直升机分队 | I51: =VLOOKUP(H51,保障组织结构树!C:E,3,0) -> z17
A52: 51 | B52: 综合武器模拟器+电源 | D52: =B52&IF(C52<>"","-"&C52,"") -> 综合武器模拟器+电源 | E52: Z20 | F52: 1 | G52: 套 | H52: 舰载直升机分队 | I52: =VLOOKUP(H52,保障组织结构树!C:E,3,0) -> z17
A53: 52 | B53: 测振设备 | D53: =B53&IF(C53<>"","-"&C53,"") -> 测振设备 | E53: Z20 | F53: 1 | G53: 套 | H53: 舰载直升机分队 | I53: =VLOOKUP(H53,保障组织结构树!C:E,3,0) -> z17
A54: 53 | B54: 军械设备包 | D54: =B54&IF(C54<>"","-"&C54,"") -> 军械设备包 | E54: Z20 | F54: 1 | G54: 套 | H54: 舰载直升机分队 | I54: =VLOOKUP(H54,保障组织结构树!C:E,3,0) -> z17
A55: 54 | B55: 振动信号分析仪 | D55: =B55&IF(C55<>"","-"&C55,"") -> 振动信号分析仪 | E55: Z20 | F55: 1 | G55: 套 | H55: 舰载直升机分队 | I55: =VLOOKUP(H55,保障组织结构树!C:E,3,0) -> z17
A56: 55 | B56: 液压工具箱 | D56: =B56&IF(C56<>"","-"&C56,"") -> 液压工具箱 | E56: Z20 | F56: 1 | G56: 套 | H56: 舰载直升机分队 | I56: =VLOOKUP(H56,保障组织结构树!C:E,3,0) -> z17
A57: 56 | B57: 操纵工具箱 | D57: =B57&IF(C57<>"","-"&C57,"") -> 操纵工具箱 | E57: Z20 | F57: 1 | G57: 套 | H57: 舰载直升机分队 | I57: =VLOOKUP(H57,保障组织结构树!C:E,3,0) -> z17
A58: 57 | B58: 声纳信号模拟器 | D58: =B58&IF(C58<>"","-"&C58,"") -> 声纳信号模拟器 | E58: Z20 | F58: 1 | G58: 套 | H58: 舰载直升机分队 | I58: =VLOOKUP(H58,保障组织结构树!C:E,3,0) -> z17
A59: 58 | B59: 水下分机模拟器 | D59: =B59&IF(C59<>"","-"&C59,"") -> 水下分机模拟器 | E59: Z20 | F59: 1 | G59: 套 | H59: 舰载直升机分队 | I59: =VLOOKUP(H59,保障组织结构树!C:E,3,0) -> z17
... A110: 109 | B110: 登机梯 | D110: =B110&IF(C110<>"","-"&C110,"") -> 登机梯 | E110: E2D | F110: 1 | G110: 套 | H110: 舰载预警机分队 | I110: =VLOOKUP(H110,保障组织结构树!C:E,3,0) -> z18
A111: 110 | B111: 挂弹车 | D111: =B111&IF(C111<>"","-"&C111,"") -> 挂弹车 | F111: 10 | G111: 辆 | H111: 航空联队（勤务） | I111: =VLOOKUP(H111,保障组织结构树!C:E,3,0) -> z19
A112: 111 | B112: 牵引车 | D112: =B112&IF(C112<>"","-"&C112,"") -> 牵引车 | F112: 10 | G112: 辆 | H112: 航空联队（勤务） | I112: =VLOOKUP(H112,保障组织结构树!C:E,3,0) -> z19
A113: 112 | B113: 电源车 | D113: =B113&IF(C113<>"","-"&C113,"") -> 电源车 | F113: 4 | G113: 辆 | H113: 航空联队（勤务） | I113: =VLOOKUP(H113,保障组织结构树!C:E,3,0) -> z19
A114: 113 | B114: 惯导车 | D114: =B114&IF(C114<>"","-"&C114,"") -> 惯导车 | F114: 4 | G114: 辆 | H114: 航空联队（勤务） | I114: =VLOOKUP(H114,保障组织结构树!C:E,3,0) -> z19
A115: 114 | B115: 装退弹工具和保险销 | D115: =B115&IF(C115<>"","-"&C115,"") -> 装退弹工具和保险销 | F115: 4 | G115: 套 | H115: 航空联队（勤务） | I115: =VLOOKUP(H115,保障组织结构树!C:E,3,0) -> z19
A116: 115 | B116: 万用表 | D116: =B116&IF(C116<>"","-"&C116,"") -> 万用表 | F116: 4 | G116: 个 | H116: 航空联队（勤务） | I116: =VLOOKUP(H116,保障组织结构树!C:E,3,0) -> z19
A117: 116 | B117: 地勤帽DM-3 | D117: =B117&IF(C117<>"","-"&C117,"") -> 地勤帽DM-3 | F117: 4 | G117: 个 | H117: 航空联队（勤务） | I117: =VLOOKUP(H117,保障组织结构树!C:E,3,0) -> z19
A118: 117 | B118: 供氧车 | D118: =B118&IF(C118<>"","-"&C118,"") -> 供氧车 | F118: 4 | G118: 辆 | H118: 航空联队（勤务） | I118: =VLOOKUP(H118,保障组织结构树!C:E,3,0) -> z19
A119: 118 | B119: 891时间同步仪 | D119: =B119&IF(C119<>"","-"&C119,"") -> 891时间同步仪 | F119: 4 | G119: 个 | H119: 航空联队（勤务） | I119: =VLOOKUP(H119,保障组织结构树!C:E,3,0) -> z19
A120: 119 | B120: 装退弹工具 | D120: =B120&IF(C120<>"","-"&C120,"") -> 装退弹工具 | F120: 4 | G120: 个 | H120: 航空联队（勤务） | I120: =VLOOKUP(H120,保障组织结构树!C:E,3,0) -> z19

Sheet 备件
A1: id | B1: 名称 | C1: 数量
A2: LRU-RW-01 | B2: 任务计算机模块 | C2: 5
A3: LRU-LD-02 | B3: 雷达接收机模块 | C3: 5
A4: LRU-GD-03 | B4: 惯导处理模块 | C4: 5
A5: LRU-YY-01 | B5: 液压泵控制器 | C5: 5
A6: LRU-ZD-02 | B6: 作动筒监测组件 | C6: 5
A7: LRU-RY-01 | B7: 燃油计量控制器 | C7: 5
A8: LRU-QD-02 | B8: 起动控制盒 | C8: 5
A9: LRU-BD-01 | B9: 北斗导航接收机 | C9: 5
A10: LRU-TX-02 | B10: 机载通信终端 | C10: 5
A11: LRU-JS-01 | B11: 主减速器监测单元 | C11: 5
A12: LRU-WJ-02 | B12: 尾桨控制组件 | C12: 5
A13: LRU-HK-01 | B13: 火控处理器 | C13: 5
... A20: LRU-WT-01 | B20: 卫通加密模块 | C20: 5

Sheet 弹药建模
A1: 名称 | B1: 型号 | C1: 数量
A2: PL10 | B2: FX-02 | C2: 1000
A3: PL15 | B3: FX-03 | C3: 1000
A4: YJ83 | C4: 1000
A5: PL12 | C5: 1000
A6: PL16B | C6: 1000
A7: YJ15 | C7: 1000
A8: YU7 | C8: 1000
A9: H1 | C9: 1000

Sheet 使用保障方案
A1: 保障方案名称 | B1: 保障方案-按阶段 | C1: 类型 | D1: 最大工作时间参考(min) | E1: 仿真运行规则
A2: F15方案1 | B2: F15-方案1-直接 | C2: 直接 | D2: 130 | E2: 先到先服务
A3: F15方案1 | B3: F15-方案1-再次 | C3: 再次 | D3: 30 | E3: 先到先服务
A4: F15方案1 | B4: F15-方案1-飞行后 | C4: 飞行后 | D4: 110 | E4: 先到先服务
A5: F35方案1 | B5: F35-方案1-直接 | C5: 直接 | D5: 130 | E5: 先到先服务
A6: F35方案1 | B6: F35-方案1-再次 | C6: 再次 | D6: 30 | E6: 先到先服务
A7: F35方案1 | B7: F35-方案1-飞行后 | C7: 飞行后 | D7: 110 | E7: 先到先服务
A8: Z20方案1 | B8: Z20方案1-直接 | C8: 直接 | D8: 130 | E8: 先到先服务
A9: Z20方案1 | B9: Z20方案1-再次 | C9: 再次 | D9: 30 | E9: 先到先服务
A10: Z20方案1 | B10: Z20方案1-飞行后 | C10: 飞行后 | D10: 110 | E10: 先到先服务
A11: E2D方案1 | B11: E2D方案1-直接 | C11: 直接 | D11: 130 | E11: 先到先服务
A12: E2D方案1 | B12: E2D方案1-再次 | C12: 再次 | D12: 30 | E12: 先到先服务
A13: E2D方案1 | B13: E2D方案1-飞行后 | C13: 飞行后 | D13: 110 | E13: 先到先服务

Sheet 使用保障活动清单
A1: 机型 | B1: 保障方案-按阶段 | C1: 作业id | D1: 作业项 | E1: 紧前作业id | F1: 工期(min)
A2: F15 | B2: F15-方案1-直接 | C2: j42 | D2: =VLOOKUP(使用保障活动清单!C2,基本保障活动列表库!C:D,2,0) -> F15-写卡 | F2: =VLOOKUP(C2,基本保障活动列表库!C:E,3,0) -> 15
A3: F15 | B3: F15-方案1-直接 | C3: j43 | D3: =VLOOKUP(使用保障活动清单!C3,基本保障活动列表库!C:D,2,0) -> F15-外观检查 | E3: =C2 -> j42 | F3: =VLOOKUP(C3,基本保障活动列表库!C:E,3,0) -> 30
A4: F15 | B4: F15-方案1-直接 | C4: j44 | D4: =VLOOKUP(使用保障活动清单!C4,基本保障活动列表库!C:D,2,0) -> F15-接通空调 | E4: =C3 -> j43 | F4: =VLOOKUP(C4,基本保障活动列表库!C:E,3,0) -> 10
A5: F15 | B5: F15-方案1-直接 | C5: j45 | D5: =VLOOKUP(使用保障活动清单!C5,基本保障活动列表库!C:D,2,0) -> F15-装干扰弹 | E5: j43 | F5: =VLOOKUP(C5,基本保障活动列表库!C:E,3,0) -> 10
A6: F15 | B6: F15-方案1-直接 | C6: j46 | D6: =VLOOKUP(使用保障活动清单!C6,基本保障活动列表库!C:D,2,0) -> F15-挂弹 | E6: =C5 -> j45 | F6: =VLOOKUP(C6,基本保障活动列表库!C:E,3,0) -> 60
A7: F15 | B7: F15-方案1-直接 | C7: j47 | D7: =VLOOKUP(使用保障活动清单!C7,基本保障活动列表库!C:D,2,0) -> F15-接通电缆 | E7: =C6 -> j46 | F7: =VLOOKUP(C7,基本保障活动列表库!C:E,3,0) -> 2
A8: F15 | B8: F15-方案1-直接 | C8: j48 | D8: =VLOOKUP(使用保障活动清单!C8,基本保障活动列表库!C:D,2,0) -> F15-加载数据 | E8: =C7 -> j47 | F8: =VLOOKUP(C8,基本保障活动列表库!C:E,3,0) -> 10
A9: F15 | B9: F15-方案1-直接 | C9: j49 | D9: =VLOOKUP(使用保障活动清单!C9,基本保障活动列表库!C:D,2,0) -> F15-通电 | E9: =C8 -> j48 | F9: =VLOOKUP(C9,基本保障活动列表库!C:E,3,0) -> 20
A10: F15 | B10: F15-方案1-直接 | C10: j50 | D10: =VLOOKUP(使用保障活动清单!C10,基本保障活动列表库!C:D,2,0) -> F15-挂载武器通电 | E10: =C9 -> j49 | F10: =VLOOKUP(C10,基本保障活动列表库!C:E,3,0) -> 10
A11: F15 | B11: F15-方案1-直接 | C11: j51 | D11: =VLOOKUP(使用保障活动清单!C11,基本保障活动列表库!C:D,2,0) -> F15-氧气充填 | E11: =C10 -> j50 | F11: =VLOOKUP(C11,基本保障活动列表库!C:E,3,0) -> 5
A12: F15 | B12: F15-方案1-直接 | C12: j52 | D12: =VLOOKUP(使用保障活动清单!C12,基本保障活动列表库!C:D,2,0) -> F15-氮气充填 | E12: =C11 -> j51 | F12: =VLOOKUP(C12,基本保障活动列表库!C:E,3,0) -> 5
A13: F15 | B13: F15-方案1-直接 | C13: j53 | D13: =VLOOKUP(使用保障活动清单!C13,基本保障活动列表库!C:D,2,0) -> F15-燃油充填 | E13: =C12 -> j52 | F13: =VLOOKUP(C13,基本保障活动列表库!C:E,3,0) -> 10
A14: F15 | B14: F15-方案1-直接 | C14: j54 | D14: =VLOOKUP(使用保障活动清单!C14,基本保障活动列表库!C:D,2,0) -> F15-滑油检查 | E14: =C13 -> j53 | F14: =VLOOKUP(C14,基本保障活动列表库!C:E,3,0) -> 5
A15: F15 | B15: F15-方案1-直接 | C15: j55 | D15: =VLOOKUP(使用保障活动清单!C15,基本保障活动列表库!C:D,2,0) -> F15-流道检查 | E15: =C14 -> j54 | F15: =VLOOKUP(C15,基本保障活动列表库!C:E,3,0) -> 5
A16: F15 | B16: F15-方案1-直接 | C16: j56 | D16: =VLOOKUP(使用保障活动清单!C16,基本保障活动列表库!C:D,2,0) -> F15-暖机电传 | E16: =C15 -> j55 | F16: =VLOOKUP(C16,基本保障活动列表库!C:E,3,0) -> 15
A17: F15 | B17: F15-方案1-直接 | C17: j57 | D17: =VLOOKUP(使用保障活动清单!C17,基本保障活动列表库!C:D,2,0) -> F15-拔座舱内保险 | E17: =C16 -> j56 | F17: =VLOOKUP(C17,基本保障活动列表库!C:E,3,0) -> 1
... A22: F15 | B22: F15-方案1-直接 | C22: j62 | D22: =VLOOKUP(使用保障活动清单!C22,基本保障活动列表库!C:D,2,0) -> F15-清点工用具 | E22: =C21 -> j61 | F22: =VLOOKUP(C22,基本保障活动列表库!C:E,3,0) -> 3
A23: F15 | B23: F15-方案1-再次 | C23: j43 | D23: =VLOOKUP(使用保障活动清单!C23,基本保障活动列表库!C:D,2,0) -> F15-外观检查 | F23: =VLOOKUP(C23,基本保障活动列表库!C:E,3,0) -> 30
A24: F15 | B24: F15-方案1-再次 | C24: j44 | D24: =VLOOKUP(使用保障活动清单!C24,基本保障活动列表库!C:D,2,0) -> F15-接通空调 | E24: j43 | F24: =VLOOKUP(C24,基本保障活动列表库!C:E,3,0) -> 10
A25: F15 | B25: F15-方案1-再次 | C25: j42 | D25: =VLOOKUP(使用保障活动清单!C25,基本保障活动列表库!C:D,2,0) -> F15-写卡 | E25: j43 | F25: =VLOOKUP(C25,基本保障活动列表库!C:E,3,0) -> 15
A26: F15 | B26: F15-方案1-再次 | C26: j48 | D26: =VLOOKUP(使用保障活动清单!C26,基本保障活动列表库!C:D,2,0) -> F15-加载数据 | E26: j43 | F26: =VLOOKUP(C26,基本保障活动列表库!C:E,3,0) -> 10
A27: F15 | B27: F15-方案1-再次 | C27: j70 | D27: =VLOOKUP(使用保障活动清单!C27,基本保障活动列表库!C:D,2,0) -> F15-通电检查-再次 | E27: j43 | F27: =VLOOKUP(C27,基本保障活动列表库!C:E,3,0) -> 20
A28: F15 | B28: F15-方案1-再次 | C28: j57 | D28: =VLOOKUP(使用保障活动清单!C28,基本保障活动列表库!C:D,2,0) -> F15-拔座舱内保险 | E28: j43 | F28: =VLOOKUP(C28,基本保障活动列表库!C:E,3,0) -> 1
A29: F15 | B29: F15-方案1-再次 | C29: j71 | D29: =VLOOKUP(使用保障活动清单!C29,基本保障活动列表库!C:D,2,0) -> F15-座椅通电 | E29: j43 | F29: =VLOOKUP(C29,基本保障活动列表库!C:E,3,0) -> 1
A30: F15 | B30: F15-方案1-再次 | C30: j46 | D30: =VLOOKUP(使用保障活动清单!C30,基本保障活动列表库!C:D,2,0) -> F15-挂弹 | E30: j43 | F30: =VLOOKUP(C30,基本保障活动列表库!C:E,3,0) -> 60
A31: F15 | B31: F15-方案1-再次 | C31: j50 | D31: =VLOOKUP(使用保障活动清单!C31,基本保障活动列表库!C:D,2,0) -> F15-挂载武器通电 | E31: j43 | F31: =VLOOKUP(C31,基本保障活动列表库!C:E,3,0) -> 10
A32: F15 | B32: F15-方案1-再次 | C32: j47 | D32: =VLOOKUP(使用保障活动清单!C32,基本保障活动列表库!C:D,2,0) -> F15-接通电缆 | E32: j43 | F32: =VLOOKUP(C32,基本保障活动列表库!C:E,3,0) -> 2
A33: F15 | B33: F15-方案1-再次 | C33: j51 | D33: =VLOOKUP(使用保障活动清单!C33,基本保障活动列表库!C:D,2,0) -> F15-氧气充填 | E33: j43 | F33: =VLOOKUP(C33,基本保障活动列表库!C:E,3,0) -> 5
A34: F15 | B34: F15-方案1-再次 | C34: j72 | D34: =VLOOKUP(使用保障活动清单!C34,基本保障活动列表库!C:D,2,0) -> F15-通电检查 | E34: j43 | F34: =VLOOKUP(C34,基本保障活动列表库!C:E,3,0) -> 20
A35: F15 | B35: F15-方案1-再次 | C35: j59 | D35: =VLOOKUP(使用保障活动清单!C35,基本保障活动列表库!C:D,2,0) -> F15-惯导 | E35: j43 | F35: =VLOOKUP(C35,基本保障活动列表库!C:E,3,0) -> 15
... A40: F15 | B40: F15-方案1-再次 | C40: j55 | D40: =VLOOKUP(使用保障活动清单!C40,基本保障活动列表库!C:D,2,0) -> F15-流道检查 | E40: j43 | F40: =VLOOKUP(C40,基本保障活动列表库!C:E,3,0) -> 5
A41: F15 | B41: F15-方案1-飞行后 | C41: j73 | D41: =VLOOKUP(使用保障活动清单!C41,基本保障活动列表库!C:D,2,0) -> F15-机械外观检查 | F41: =VLOOKUP(C41,基本保障活动列表库!C:E,3,0) -> 30
A42: F15 | B42: F15-方案1-飞行后 | C42: j74 | D42: =VLOOKUP(使用保障活动清单!C42,基本保障活动列表库!C:D,2,0) -> F15-插座舱内保险 | E42: j73 | F42: =VLOOKUP(C42,基本保障活动列表库!C:E,3,0) -> 1
A43: F15 | B43: F15-方案1-飞行后 | C43: j75 | D43: =VLOOKUP(使用保障活动清单!C43,基本保障活动列表库!C:D,2,0) -> F15-插起落架下位锁保险销 | E43: j73 | F43: =VLOOKUP(C43,基本保障活动列表库!C:E,3,0) -> 1
A44: F15 | B44: F15-方案1-飞行后 | C44: j76 | D44: =VLOOKUP(使用保障活动清单!C44,基本保障活动列表库!C:D,2,0) -> F15-退弹 | E44: j73 | F44: =VLOOKUP(C44,基本保障活动列表库!C:E,3,0) -> 3
A45: F15 | B45: F15-方案1-飞行后 | C45: j77 | D45: =VLOOKUP(使用保障活动清单!C45,基本保障活动列表库!C:D,2,0) -> F15-插水上记录漂浮记录保险 | E45: j73 | F45: =VLOOKUP(C45,基本保障活动列表库!C:E,3,0) -> 2
A46: F15 | B46: F15-方案1-飞行后 | C46: j78 | D46: =VLOOKUP(使用保障活动清单!C46,基本保障活动列表库!C:D,2,0) -> F15-关闭发动机补养开关 | E46: j73 | F46: =VLOOKUP(C46,基本保障活动列表库!C:E,3,0) -> 2
A47: F15 | B47: F15-方案1-飞行后 | C47: j79 | D47: =VLOOKUP(使用保障活动清单!C47,基本保障活动列表库!C:D,2,0) -> F15-插空速管保护套、风标保护套 | E47: j73 | F47: =VLOOKUP(C47,基本保障活动列表库!C:E,3,0) -> 5
A48: F15 | B48: F15-方案1-飞行后 | C48: j80 | D48: =VLOOKUP(使用保障活动清单!C48,基本保障活动列表库!C:D,2,0) -> F15-外观检查-飞行后 | E48: j73 | F48: =VLOOKUP(C48,基本保障活动列表库!C:E,3,0) -> 20
...

Sheet 预防性维修活动
A1: 机型 | B1: 方案名称 | C1: 计划停机小时 | D1: 启动日历时间 | E1: 日历日间隔 | F1: 日历日间隔上下浮动比例(%) | G1: 启动飞行小时 | H1: 飞行小时间隔 | I1: 飞行小时上下浮动比例(%) | J1: 启动起落次数 | K1: 起落次数间隔 | L1: 起落次数间隔上下浮动比例(%) | M1: 作业id | N1: 作业项 | O1: 紧前作业 | P1: 工时(min)
A2: F15 | B2: 25小时周期性工作 | C2: 8 | G2: 启用 | H2: 8 | I2: 10 | M2: REP-001 | N2: 定检航电检查 | P2: 40
A3: F15 | B3: 25小时周期性工作 | C3: 8 | G3: 启用 | H3: 8 | I3: 10 | M3: REP-002 | N3: 发动机拆卸 | O3: =M2 -> REP-001 | P3: 120
A4: F15 | B4: 25小时周期性工作 | C4: 8 | G4: 启用 | H4: 8 | I4: 10 | M4: REP-003 | N4: 起落架收放测试 | O4: =M3 -> REP-002 | P4: 45
A5: F15 | B5: 25小时周期性工作 | C5: 8 | G5: 启用 | H5: 8 | I5: 10 | M5: REP-004 | N5: 燃油系统密封性检查 | O5: =M4 -> REP-003 | P5: 35
A6: F15 | B6: 25小时周期性工作 | C6: 8 | G6: 启用 | H6: 8 | I6: 10 | M6: REP-005 | N6: 机载雷达效能测试 | O6: =M5 -> REP-004 | P6: 60
A7: F15 | B7: 25小时周期性工作 | C7: 8 | G7: 启用 | H7: 8 | I7: 10 | M7: REP-006 | N7: 通信链路校准 | P7: 25
A8: F15 | B8: 25小时周期性工作 | C8: 8 | G8: 启用 | H8: 8 | I8: 10 | M8: REP-007 | N8: 武器外挂架检查 | P8: 30
A9: F15 | B9: 50小时周期性工作 | C9: 8 | G9: 启用 | H9: 50 | I9: 10 | M9: REP-012 | N9: 旋翼传动系统振动检测 | P9: 52
A10: F15 | B10: 50小时周期性工作 | C10: 8 | G10: 启用 | H10: 50 | I10: 10 | M10: REP-013 | N10: 通信导航系统校线 | O10: =M9 -> REP-012 | P10: 28
A11: F15 | B11: 机械日维护 | C11: 24 | D11: 启用 | E11: 7 | F11: 0 | M11: REP-001 | N11: 定检航电检查 | P11: 40
A12: F15 | B12: 机械日维护 | C12: 24 | D12: 启用 | E12: 7 | F12: 0 | M12: REP-002 | N12: 发动机拆卸 | O12: =M11 -> REP-001 | P12: 120
A13: F15 | B13: 机械日维护 | C13: 24 | D13: 启用 | E13: 7 | F13: 0 | M13: REP-003 | N13: 起落架收放测试 | O13: =M12 -> REP-002 | P13: 45
A14: F15 | B14: 机械日维护 | C14: 24 | D14: 启用 | E14: 7 | F14: 0 | M14: REP-004 | N14: 燃油系统密封性检查 | O14: =M13 -> REP-003 | P14: 35
A15: F15 | B15: 机械日维护 | C15: 24 | D15: 启用 | E15: 7 | F15: 0 | M15: REP-005 | N15: 机载雷达效能测试 | O15: =M14 -> REP-004 | P15: 60
A16: F15 | B16: 机械日维护 | C16: 24 | D16: 启用 | E16: 7 | F16: 0 | M16: REP-006 | N16: 通信链路校准 | P16: 25
A17: F15 | B17: 机械日维护 | C17: 24 | D17: 启用 | E17: 7 | F17: 0 | M17: REP-007 | N17: 武器外挂架检查 | P17: 30
A18: F35 | B18: 50小时周期性工作 | C18: 8 | G18: 启用 | H18: 50 | I18: 10 | M18: REP-001 | N18: 定检航电检查 | P18: 40
A19: F35 | B19: 50小时周期性工作 | C19: 8 | G19: 启用 | H19: 50 | I19: 10 | M19: REP-002 | N19: 发动机拆卸 | O19: =M18 -> REP-001 | P19: 120
A20: F35 | B20: 50小时周期性工作 | C20: 8 | G20: 启用 | H20: 50 | I20: 10 | M20: REP-003 | N20: 起落架收放测试 | O20: =M19 -> REP-002 | P20: 45
A21: F35 | B21: 50小时周期性工作 | C21: 8 | G21: 启用 | H21: 50 | I21: 10 | M21: REP-004 | N21: 燃油系统密封性检查 | O21: =M20 -> REP-003 | P21: 35
A22: F35 | B22: 50小时周期性工作 | C22: 8 | G22: 启用 | H22: 50 | I22: 10 | M22: REP-005 | N22: 机载雷达效能测试 | O22: =M21 -> REP-004 | P22: 60
A23: F35 | B23: 50小时周期性工作 | C23: 8 | G23: 启用 | H23: 50 | I23: 10 | M23: REP-006 | N23: 通信链路校准 | P23: 25
A24: F35 | B24: 50小时周期性工作 | C24: 8 | G24: 启用 | H24: 50 | I24: 10 | M24: REP-007 | N24: 武器外挂架检查 | P24: 30
A25: F35 | B25: 机械日维护 | C25: 24 | D25: 启用 | E25: 7 | F25: 0 | M25: REP-001 | N25: 定检航电检查 | P25: 40
A26: F35 | B26: 机械日维护 | C26: 24 | D26: 启用 | E26: 7 | F26: 0 | M26: REP-002 | N26: 发动机拆卸 | O26: =M25 -> REP-001 | P26: 120
A27: F35 | B27: 机械日维护 | C27: 24 | D27: 启用 | E27: 7 | F27: 0 | M27: REP-003 | N27: 起落架收放测试 | O27: =M26 -> REP-002 | P27: 45
A28: F35 | B28: 机械日维护 | C28: 24 | D28: 启用 | E28: 7 | F28: 0 | M28: REP-004 | N28: 燃油系统密封性检查 | O28: =M27 -> REP-003 | P28: 35
A29: F35 | B29: 机械日维护 | C29: 24 | D29: 启用 | E29: 7 | F29: 0 | M29: REP-005 | N29: 机载雷达效能测试 | O29: =M28 -> REP-004 | P29: 60
A30: F35 | B30: 机械日维护 | C30: 24 | D30: 启用 | E30: 7 | F30: 0 | M30: REP-006 | N30: 通信链路校准 | P30: 25
A31: F35 | B31: 机械日维护 | C31: 24 | D31: 启用 | E31: 7 | F31: 0 | M31: REP-007 | N31: 武器外挂架检查 | P31: 30
A32: E2D | B32: 25小时周期性工作 | C32: 8 | G32: 启用 | H32: 25 | I32: 10 | M32: REP-012 | N32: 旋翼传动系统振动检测 | P32: 52
A33: E2D | B33: 25小时周期性工作 | C33: 8 | G33: 启用 | H33: 25 | I33: 10 | M33: REP-013 | N33: 通信导航系统校线 | O33: =M32 -> REP-012 | P33: 28
A34: E2D | B34: 25小时周期性工作 | C34: 8 | G34: 启用 | H34: 25 | I34: 10 | M34: REP-001 | N34: 定检航电检查 | P34: 40
A35: E2D | B35: 25小时周期性工作 | C35: 8 | G35: 启用 | H35: 25 | I35: 10 | M35: REP-002 | N35: 发动机拆卸 | O35: =M34 -> REP-001 | P35: 120
A36: E2D | B36: 25小时周期性工作 | C36: 8 | G36: 启用 | H36: 25 | I36: 10 | M36: REP-003 | N36: 起落架收放测试 | O36: =M35 -> REP-002 | P36: 45
A37: E2D | B37: 25小时周期性工作 | C37: 8 | G37: 启用 | H37: 25 | I37: 10 | M37: REP-004 | N37: 燃油系统密封性检查 | O37: =M36 -> REP-003 | P37: 35
A38: E2D | B38: 25小时周期性工作 | C38: 8 | G38: 启用 | H38: 25 | I38: 10 | M38: REP-005 | N38: 机载雷达效能测试 | O38: =M37 -> REP-004 | P38: 60
A39: E2D | B39: 25小时周期性工作 | C39: 8 | G39: 启用 | H39: 25 | I39: 10 | M39: REP-006 | N39: 通信链路校准 | P39: 25
A40: E2D | B40: 25小时周期性工作 | C40: 8 | G40: 启用 | H40: 25 | I40: 10 | M40: REP-007 | N40: 武器外挂架检查 | P40: 30

Sheet 修复性维修活动
A1: 维修对象id | B1: 维修对象 | C1: 平均修复时间（min） | D1: 维修类型 | E1: 作业id | F1: 作业项 | G1: 紧前作业id | H1: 工期(min)
A2: LRU-RW-01 | B2: 任务计算机模块 | C2: 30 | D2: 原位维修 | E2: REP-001 | F2: 更换故障件 | H2: 40
A3: LRU-LD-02 | B3: 雷达接收机模块 | C3: 30 | D3: 原位维修 | E3: REP-002 | F3: 更换故障件 | H3: 120
A4: LRU-GD-03 | B4: 惯导处理模块 | C4: 30 | D4: 原位维修 | E4: REP-003 | F4: 更换故障件 | H4: 45
A5: LRU-YY-01 | B5: 液压泵控制器 | C5: 30 | D5: 原位维修 | E5: REP-004 | F5: 更换故障件 | H5: 35
A6: LRU-ZD-02 | B6: 作动筒监测组件 | C6: 30 | D6: 原位维修 | E6: REP-005 | F6: 更换故障件 | H6: 60
A7: LRU-RY-01 | B7: 燃油计量控制器 | C7: 30 | D7: 原位维修 | E7: REP-006 | F7: 更换故障件 | H7: 25
A8: LRU-QD-02 | B8: 起动控制盒 | C8: 30 | D8: 原位维修 | E8: REP-007 | F8: 更换故障件 | H8: 30
A9: LRU-BD-01 | B9: 北斗导航接收机 | C9: 30 | D9: 原位维修 | E9: REP-008 | F9: 更换故障件 | H9: 40
A10: LRU-TX-02 | B10: 机载通信终端 | C10: 30 | D10: 原位维修 | E10: REP-009 | F10: 更换故障件 | H10: 120
A11: LRU-JS-01 | B11: 主减速器监测单元 | C11: 30 | D11: 原位维修 | E11: REP-010 | F11: 更换故障件 | H11: 45
A12: LRU-WJ-02 | B12: 尾桨控制组件 | C12: 30 | D12: 原位维修 | E12: REP-011 | F12: 更换故障件 | H12: 35
A13: LRU-HK-01 | B13: 火控处理器 | C13: 30 | D13: 原位维修 | E13: REP-012 | F13: 更换故障件 | H13: 60
... A20: LRU-WT-01 | B20: 卫通加密模块 | C20: 30 | D20: 原位维修 | E20: REP-019 | F20: 准备工具 | H20: 10
A21: LRU-WT-01 | B21: 卫通加密模块 | C21: 30 | D21: 原位维修 | E21: REP-020 | F21: 打开通道 | G21: =E20 -> REP-019 | H21: 5
A22: LRU-WT-01 | B22: 卫通加密模块 | C22: 30 | D22: 原位维修 | E22: REP-021 | F22: 拆除故障件 | G22: =E21 -> REP-020 | H22: 10
A23: LRU-WT-01 | B23: 卫通加密模块 | C23: 30 | D23: 原位维修 | E23: REP-022 | F23: 安装备件 | G23: =E22 -> REP-021 | H23: 20
A24: LRU-WT-01 | B24: 卫通加密模块 | C24: 30 | D24: 原位维修 | E24: REP-023 | F24: 更换后测试 | G24: =E23 -> REP-022 | H24: 30
A25: LRU-WT-01 | B25: 卫通加密模块 | C25: 30 | D25: 原位维修 | E25: REP-024 | F25: 关闭通道 | G25: =E24 -> REP-023 | H25: 10

Sheet 基本保障活动列表库
A1: 类型 | B1: 适用对象 | C1: 基本保障活动id | D1: 基本保障活动 | E1: 工期(min) | F1: 机械师 | G1: 机械员 | H1: 航电师 | I1: 航电员 | J1: 军械师 | K1: 军械员 | L1: 特设师 | M1: 特设员 | N1: 声纳师 | O1: 声纳员 | P1: 任务电子师 | Q1: 任务电子员 | R1: 勤务组 | S1: 保障设施功能 | T1: 保障设备 | U1: 保障设备数量 | V1: 弹药需求 | W1: 备件需求
A2: 使用保障 | B2: F35 | C2: j01 | D2: F35-写卡 | E2: 15 | H2: 1
A3: 使用保障 | B3: F35 | C3: j02 | D3: F35-外观检查 | E3: 30 | F3: 1 | G3: 1 | I3: 1 | M3: 1
A4: 使用保障 | B4: F35 | C4: j03 | D4: F35-接通空调 | E4: 10 | I4: 1 | R4: 舰面保障组 | S4: 座舱空调
A5: 使用保障 | B5: F35 | C5: j04 | D5: F35-装干扰弹 | E5: 10 | K5: 1
A6: 使用保障 | B6: F35 | C6: j05 | D6: F35-挂弹 | E6: 60 | J6: 1 | R6: 挂弹组 | S6: 挂弹 | T6: 挂弹车 | U6: 2 | V6: [YJ83:4,PL10:6,PL12:8,PL16B:8,YJ15:4]
A7: 使用保障 | B7: F35 | C7: j06 | D7: F35-接通电缆 | E7: 2 | M7: 1 | R7: 舰面保障组 | S7: 供电 | T7: 万用表 | U7: 1
A8: 使用保障 | B8: F35 | C8: j07 | D8: F35-加载数据 | E8: 10 | I8: 1
A9: 使用保障 | B9: F35 | C9: j08 | D9: F35-通电 | E9: 20 | I9: 1 | K9: 1 | M9: 1 | S9: 供电 | T9: 地勤帽DM-3 | U9: 1
A10: 使用保障 | B10: F35 | C10: j09 | D10: F35-挂载武器通电 | E10: 10 | K10: 1
A11: 使用保障 | B11: F35 | C11: j10 | D11: F35-氧气充填 | E11: 5 | M11: 1 | R11: 舰面保障组 | S11: 供氧
A12: 使用保障 | B12: F35 | C12: j11 | D12: F35-氮气充填 | E12: 5 | G12: 1 | R12: 舰面保障组 | S12: 供氮
A13: 使用保障 | B13: F35 | C13: j12 | D13: F35-燃油充填 | E13: 10 | G13: 1 | R13: 加油组
A14: 使用保障 | B14: F35 | C14: j13 | D14: F35-滑油检查 | E14: 5 | G14: 3 | R14: 质检组
A15: 使用保障 | B15: F35 | C15: j14 | D15: F35-流道检查 | E15: 5 | G15: 3 | R15: 流道组
A16: 使用保障 | B16: F35 | C16: j15 | D16: F35-暖机电传 | E16: 15 | G16: 1
A17: 使用保障 | B17: F35 | C17: j16 | D17: F35-拔座舱内保险 | E17: 1 | K17: 1
A18: 使用保障 | B18: F35 | C18: j17 | D18: F35-拔起落架下位锁保险销 | E18: 1 | J18: 1
A19: 使用保障 | B19: F35 | C19: j18 | D19: F35-惯导 | E19: 15 | I19: 1 | R19: 舰面保障组 | S19: 惯导 | T19: 地勤帽DM-3
A20: 使用保障 | B20: F35 | C20: j19 | D20: F35-拔水上漂浮记录器保险 | E20: 2 | M20: 1
A21: 使用保障 | B21: F35 | C21: j20 | D21: F35-文件填写 | E21: 5 | F21: 1 | G21: 1 | I21: 1 | M21: 1
A22: 使用保障 | B22: F35 | C22: j21 | D22: F35-清点工用具 | E22: 3 | F22: 1 | G22: 1 | I22: 1 | M22: 1
A23: 使用保障 | B23: F35 | C23: j22 | D23: F35-间隙异物排查 | E23: 5 | R23: 间隙异物组
A24: 使用保障 | B24: F35 | C24: j23 | D24: F35-暖机开车滑出 | E24: 20 | R24: 转运组
A25: 使用保障 | B25: F35 | C25: j24 | D25: F35-资源撤收 | E25: 3 | R25: 舰面保障组
A26: 使用保障 | B26: F35 | C26: j25 | D26: F35-放飞流程 | E26: 4 | R26: 放飞组
A27: 使用保障 | B27: F35 | C27: j26 | D27: F35-关车系留 | E27: 20 | R27: 转运组
A28: 使用保障 | B28: F35 | C28: j27 | D28: F35-接通空调-再次 | E28: 5 | I28: 1 | R28: 舰面保障组 | S28: 座舱空调
A29: 使用保障 | B29: F35 | C29: j28 | D29: F35-加载数据 | E29: 10 | I29: 1
A30: 使用保障 | B30: F35 | C30: j29 | D30: F35-通电检查-再次 | E30: 20 | I30: 1 | R30: 舰面保障组 | S30: 供电 | T30: 地勤帽DM-3
A31: 使用保障 | B31: F35 | C31: j30 | D31: F35-座椅通电 | E31: 1 | K31: 1
A32: 使用保障 | B32: F35 | C32: j31 | D32: F35-通电检查 | E32: 20 | M32: 1 | S32: 供电
A33: 使用保障 | B33: F35 | C33: j32 | D33: F35-机械外观检查 | E33: 30 | F33: 1
A34: 使用保障 | B34: F35 | C34: j33 | D34: F35-插座舱内保险 | E34: 1 | G34: 1
A35: 使用保障 | B35: F35 | C35: j34 | D35: F35-插起落架下位锁保险销 | E35: 1 | F35: 1
A36: 使用保障 | B36: F35 | C36: j35 | D36: F35-退弹 | E36: 3 | J36: 1 | R36: 挂弹组 | T36: 挂弹车
A37: 使用保障 | B37: F35 | C37: j36 | D37: F35-插水上记录漂浮记录保险 | E37: 2 | M37: 1
A38: 使用保障 | B38: F35 | C38: j37 | D38: F35-关闭发动机补养开关 | E38: 2 | M38: 1
A39: 使用保障 | B39: F35 | C39: j38 | D39: F35-插空速管保护套、风标保护套 | E39: 5 | M39: 1
A40: 使用保障 | B40: F35 | C40: j39 | D40: F35-外观检查-飞行后 | E40: 20 | I40: 1
...

Sheet 基本任务
A1: 机型 | B1: 基本任务名称 | C1: 任务编号 | D1: 装备数量 | E1: 任务时长（分钟） | F1: 准备时间（min） | G1: 取消时间（min） | H1: 使用保障活动 | I1: 任务区域描述 | J1: 更新时间
A2: F35 | B2: 对海任务 | C2: BT-20260309-001 | D2: 6 | E2: 90 | F2: 120 | G2: 20 | H2: F35方案1 | J2: 2026-03-08T09:30
A3: F15 | B3: 对海任务 | C3: BT-20260309-004 | D3: 2 | E3: 90 | F3: 130 | G3: 20 | H3: F15方案1 | J3: 2026-03-09T09:30
A4: F35 | B4: 护航任务 | C4: BT-20260310-005 | D4: 2 | E4: 120 | F4: 130 | G4: 25 | H4: F15方案1 | J4: 2026-03-10T10:30
A5: Z20 | B5: 搜救支援任务 | C5: BT-20260309-007 | D5: 1 | E5: 120 | F5: 95 | G5: 15 | H5: Z20方案1 | J5: 2026-03-10T09:30
A6: E2D | B6: 预警任务 | C6: BT-20260309-010 | D6: 1 | E6: 180 | F6: 140 | G6: 30 | H6: E2D方案1 | J6: 2026-03-11T09:30

Sheet 复合任务
A1: 复合任务名称 | B1: 序号 | C1: 基本任务名称 | D1: 装备类型 | E1: 装备数量 | F1: 编队名称 | G1: 任务下达时间 | H1: 首波次出动时刻 | I1: 单日重复次数 | J1: 间隔小时数
A2: 高强度出动剖面 | B2: 1 | C2: 对海任务 | D2: F35 | E2: 6 | F2: F35-AS-A | G2: 0.25 | H2: 0.33333333 | I2: 3 | J2: 4
A3: 高强度出动剖面 | B3: 2 | C3: 对海任务 | D3: F15 | E3: 2 | F3: F15-AS-A | G3: 0.25 | H3: 0.33333333 | I3: 3 | J3: 4
A4: 高强度出动剖面 | B4: 3 | C4: 对海任务 | D4: F35 | E4: 6 | F4: F35-AS-B | G4: 0.25 | H4: 0.375 | I4: 3 | J4: 4
A5: 高强度出动剖面 | B5: 4 | C5: 对海任务 | D5: F15 | E5: 2 | F5: F15-AS-B | G5: 0.25 | H5: 0.375 | I5: 3 | J5: 4
A6: 高强度出动剖面 | B6: 5 | C6: 对海任务 | D6: F35 | E6: 6 | F6: F35-AS-C | G6: 0.25 | H6: 0.41666667 | I6: 2 | J6: 4
A7: 高强度出动剖面 | B7: 6 | C7: 对海任务 | D7: F15 | E7: 2 | F7: F15-AS-C | G7: 0.25 | H7: 0.41666667 | I7: 2 | J7: 4
A8: 高强度出动剖面 | B8: 7 | C8: 护航任务 | D8: F35 | E8: 2 | F8: F35-SC-1 | G8: 0.25 | H8: 0.33333333 | I8: 6 | J8: 3
A9: 高强度出动剖面 | B9: 8 | C9: 护航任务 | D9: F35 | E9: 2 | F9: F35-SC-2 | G9: 0.25 | H9: 0.39583333 | I9: 6 | J9: 3
A10: 高强度出动剖面 | B10: 9 | C10: 预警任务 | D10: E2D | E10: 1 | F10: E2D-W1 | G10: 0.25 | H10: 0.33333333 | I10: 4 | J10: 4
A11: 高强度出动剖面 | B11: 10 | C11: 预警任务 | D11: E2D | E11: 1 | F11: E2D-W2 | G11: 0.25 | H11: 0.41666667 | I11: 4 | J11: 4
A12: 高强度出动剖面 | B12: 11 | C12: 搜救支援任务 | D12: Z20 | E12: 1 | F12: Z-W1 | G12: 0.25 | H12: 0.3125 | I12: 6 | J12: 3
A13: 高强度出动剖面 | B13: 12 | C13: 搜救支援任务 | D13: Z20 | E13: 1 | F13: Z-W2 | G13: 0.25 | H13: 0.375 | I13: 6 | J13: 3

Sheet 周期性任务
A1: 周期性任务名称 | B1: 星期一 | C1: 星期二 | D1: 星期三 | E1: 星期四 | F1: 星期五 | G1: 星期六 | H1: 星期日 | I1: 重复周数
A2: 周期性任务A | B2: 高强度出动剖面 | C2: 高强度出动剖面 | D2: 高强度出动剖面 | E2: 高强度出动剖面 | I2: 1

Sheet 基本使用单元
A1: 周期性任务名称 | B1: 编队名称 | C1: 装备型号 | D1: 需求数量 | E1: 成员编号
A2: 周期性任务A | B2: F35-AS-A | C2: F35 | D2: 6 | E2: F35-01,F35-02,F35-03,F35-04,F35-05,F35-06
A3: 周期性任务A | B3: F15-AS-A | C3: F15 | D3: 2 | E3: F15-01,F15-02
A4: 周期性任务A | B4: F35-AS-B | C4: F35 | D4: 6 | E4: F35-07,F35-08,F35-09,F35-10,F35-11,F35-12
A5: 周期性任务A | B5: F15-AS-B | C5: F15 | D5: 2 | E5: F15-03,F15-04
A6: 周期性任务A | B6: F35-AS-C | C6: F35 | D6: 6 | E6: F35-13,F35-14,F35-15,F35-16,F35-17,F35-18
A7: 周期性任务A | B7: F15-AS-C | C7: F15 | D7: 2 | E7: F15-05,F15-06
A8: 周期性任务A | B8: F35-SC-1 | C8: F35 | D8: 2 | E8: F35-19,F35-20
A9: 周期性任务A | B9: F35-SC-2 | C9: F35 | D9: 2 | E9: F35-21,F35-22
A10: 周期性任务A | B10: E2D-W1 | C10: E2D | D10: 1 | E10: E2D-01
A11: 周期性任务A | B11: E2D-W2 | C11: E2D | D11: 1 | E11: E2D-02
A12: 周期性任务A | B12: Z-W1 | C12: Z20 | D12: 1 | E12: Z20-01
A13: 周期性任务A | B13: Z-W2 | C13: Z20 | D13: 1 | E13: Z20-02
